2025-01-06 22:20:45 CRITICAL auto_prep.preprocessing.outlier_detecting: <class 'tuple'>
2025-01-06 22:20:45 ERROR auto_prep.preprocessing.outlier_detecting: Failed to fit_transform OutlierDetector method: zscore: 'tuple' object has no attribute 'shape'
Traceback (most recent call last):
  File "/Users/pawelp/Desktop/education/pw/automl/AutoPrep/auto_prep/preprocessing/outlier_detecting.py", line 103, in fit_transform
    transformed_X = self.fit(X).transform(X)
                    ^^^^^^^^^^^
  File "/Users/pawelp/Desktop/education/pw/automl/AutoPrep/auto_prep/preprocessing/outlier_detecting.py", line 41, in fit
    logger.start_operation(f"Numerical data fit ({X.shape[1]} columns).")
                                                  ^^^^^^^
AttributeError: 'tuple' object has no attribute 'shape'
2025-01-06 22:20:45 DEBUG auto_prep.preprocessing.outlier_detecting: ✓ Fitting ans transforming data with OutlierDetector method: zscore
2025-01-06 22:21:23 DEBUG auto_prep.preprocessing.outlier_detecting: → Fitting ans transforming data with OutlierDetector method: zscore
2025-01-06 22:21:23 CRITICAL auto_prep.preprocessing.outlier_detecting: <class 'pandas.core.frame.DataFrame'>
2025-01-06 22:21:23 DEBUG auto_prep.preprocessing.outlier_detecting: → Numerical data fit (14 columns).
2025-01-06 22:21:23 DEBUG auto_prep.preprocessing.outlier_detecting: ✓ Numerical data fit (14 columns).
2025-01-06 22:21:23 DEBUG auto_prep.preprocessing.outlier_detecting: → Transforming data for outlier detection.
2025-01-06 22:21:23 DEBUG auto_prep.preprocessing.outlier_detecting: → Detecting outliers using Z-score.
2025-01-06 22:21:23 DEBUG auto_prep.preprocessing.outlier_detecting: ✓ Detecting outliers using Z-score.
2025-01-06 22:21:23 DEBUG auto_prep.preprocessing.outlier_detecting: Found 2 outliers.
2025-01-06 22:21:23 ERROR auto_prep.preprocessing.outlier_detecting: Error in Outlier Detection: '[78, 140, 192, 208, 254, 309, 351, 351, 361, 367, 413, 490, 567, 610, 613, 636, 636, 661, 672, 672, 679, 705, 708, 731, 746, 767, 777, 933, 936, 939, 942, 988, 997, 1034, 1042] not found in axis'
2025-01-06 22:21:23 ERROR auto_prep.preprocessing.outlier_detecting: Failed to fit_transform OutlierDetector method: zscore: '[78, 140, 192, 208, 254, 309, 351, 351, 361, 367, 413, 490, 567, 610, 613, 636, 636, 661, 672, 672, 679, 705, 708, 731, 746, 767, 777, 933, 936, 939, 942, 988, 997, 1034, 1042] not found in axis'
Traceback (most recent call last):
  File "/Users/pawelp/Desktop/education/pw/automl/AutoPrep/auto_prep/preprocessing/outlier_detecting.py", line 103, in fit_transform
    transformed_X = self.fit(X).transform(X)
                    ^^^^^^^^^^^^^^^^^^^^^^^^
  File "/opt/homebrew/Caskroom/miniconda/base/envs/automl/lib/python3.11/site-packages/sklearn/utils/_set_output.py", line 157, in wrapped
    data_to_wrap = f(self, X, *args, **kwargs)
                   ^^^^^^^^^^^^^^^^^^^^^^^^^^^
  File "/Users/pawelp/Desktop/education/pw/automl/AutoPrep/auto_prep/preprocessing/outlier_detecting.py", line 84, in transform
    raise e
  File "/Users/pawelp/Desktop/education/pw/automl/AutoPrep/auto_prep/preprocessing/outlier_detecting.py", line 80, in transform
    X = X.drop(outliers[0])
        ^^^^^^^^^^^^^^^^^^^
  File "/opt/homebrew/Caskroom/miniconda/base/envs/automl/lib/python3.11/site-packages/pandas/util/_decorators.py", line 331, in wrapper
    return func(*args, **kwargs)
           ^^^^^^^^^^^^^^^^^^^^^
  File "/opt/homebrew/Caskroom/miniconda/base/envs/automl/lib/python3.11/site-packages/pandas/core/frame.py", line 5399, in drop
    return super().drop(
           ^^^^^^^^^^^^^
  File "/opt/homebrew/Caskroom/miniconda/base/envs/automl/lib/python3.11/site-packages/pandas/util/_decorators.py", line 331, in wrapper
    return func(*args, **kwargs)
           ^^^^^^^^^^^^^^^^^^^^^
  File "/opt/homebrew/Caskroom/miniconda/base/envs/automl/lib/python3.11/site-packages/pandas/core/generic.py", line 4505, in drop
    obj = obj._drop_axis(labels, axis, level=level, errors=errors)
          ^^^^^^^^^^^^^^^^^^^^^^^^^^^^^^^^^^^^^^^^^^^^^^^^^^^^^^^^
  File "/opt/homebrew/Caskroom/miniconda/base/envs/automl/lib/python3.11/site-packages/pandas/core/generic.py", line 4546, in _drop_axis
    new_axis = axis.drop(labels, errors=errors)
               ^^^^^^^^^^^^^^^^^^^^^^^^^^^^^^^^
  File "/opt/homebrew/Caskroom/miniconda/base/envs/automl/lib/python3.11/site-packages/pandas/core/indexes/base.py", line 6934, in drop
    raise KeyError(f"{list(labels[mask])} not found in axis")
KeyError: '[78, 140, 192, 208, 254, 309, 351, 351, 361, 367, 413, 490, 567, 610, 613, 636, 636, 661, 672, 672, 679, 705, 708, 731, 746, 767, 777, 933, 936, 939, 942, 988, 997, 1034, 1042] not found in axis'
2025-01-06 22:23:17 DEBUG auto_prep.preprocessing.outlier_detecting: → Fitting ans transforming data with OutlierDetector method: zscore
2025-01-06 22:23:17 CRITICAL auto_prep.preprocessing.outlier_detecting: <class 'pandas.core.frame.DataFrame'>
2025-01-06 22:23:17 DEBUG auto_prep.preprocessing.outlier_detecting: → Numerical data fit (14 columns).
